Traceback (most recent call last):
  File "/home/dmarx/miniconda3/envs/sandbox/lib/python3.9/site-packages/nbclient/client.py", line 626, in _async_poll_for_reply
    msg = await ensure_async(self.kc.shell_channel.get_msg(timeout=new_timeout))
  File "/home/dmarx/miniconda3/envs/sandbox/lib/python3.9/site-packages/nbclient/util.py", line 96, in ensure_async
    result = await obj
  File "/home/dmarx/.local/lib/python3.9/site-packages/jupyter_client/channels.py", line 230, in get_msg
    raise Empty
_queue.Empty

During handling of the above exception, another exception occurred:

Traceback (most recent call last):
  File "/home/dmarx/miniconda3/envs/sandbox/lib/python3.9/site-packages/jupyter_cache/executors/utils.py", line 51, in single_nb_execution
    executenb(
  File "/home/dmarx/miniconda3/envs/sandbox/lib/python3.9/site-packages/nbclient/client.py", line 1093, in execute
    return NotebookClient(nb=nb, resources=resources, km=km, **kwargs).execute()
  File "/home/dmarx/miniconda3/envs/sandbox/lib/python3.9/site-packages/nbclient/util.py", line 84, in wrapped
    return just_run(coro(*args, **kwargs))
  File "/home/dmarx/miniconda3/envs/sandbox/lib/python3.9/site-packages/nbclient/util.py", line 62, in just_run
    return loop.run_until_complete(coro)
  File "/home/dmarx/miniconda3/envs/sandbox/lib/python3.9/asyncio/base_events.py", line 642, in run_until_complete
    return future.result()
  File "/home/dmarx/miniconda3/envs/sandbox/lib/python3.9/site-packages/nbclient/client.py", line 559, in async_execute
    await self.async_execute_cell(
  File "/home/dmarx/miniconda3/envs/sandbox/lib/python3.9/site-packages/nbclient/client.py", line 838, in async_execute_cell
    exec_reply = await self.task_poll_for_reply
  File "/home/dmarx/miniconda3/envs/sandbox/lib/python3.9/site-packages/nbclient/client.py", line 650, in _async_poll_for_reply
    await self._async_handle_timeout(timeout, cell)
  File "/home/dmarx/miniconda3/envs/sandbox/lib/python3.9/site-packages/nbclient/client.py", line 697, in _async_handle_timeout
    raise CellTimeoutError.error_from_timeout_and_cell(
nbclient.exceptions.CellTimeoutError: A cell timed out while it was being executed, after 300 seconds.
The message was: Cell execution timed out.
Here is a preview of the cell contents:
-------------------
#%%capture
!python -m pytti.workhorse \
    --multirun \
    conf=my_first_pytti_art3 \
    vqgan_model=sflckr,imagenet,coco \
    +perceptors=RN50x4,ViTB16,ViTB32_RN50x4

# 9 runs is plenty. this is just a tutorial. Changing it to the following would result in 50 runs (5*10):
#    vqgan_model=sflckr,imagenet,coco,wikiart,openimages \
#    +perceptors=RN50,RN101,RN50x4,RN50x16,RN50x64,ViTB16,ViTL14,ViTB32_RN50,ViTB32_RN101,ViTB32_RN50x4
-------------------

